<?xml version="1.0" encoding="UTF-8"?>
<testng-results skipped="0" failed="1" ignored="0" total="3" passed="2">
  <reporter-output>
  </reporter-output>
  <suite name="s1" duration-ms="46" started-at="2020-12-03T11:07:49 CST" finished-at="2020-12-03T11:07:49 CST">
    <groups>
    </groups>
    <test name="t2" duration-ms="46" started-at="2020-12-03T11:07:49 CST" finished-at="2020-12-03T11:07:49 CST">
      <class name="com.webtest.demo.Test02">
        <test-method status="PASS" signature="test01()[pri:0, instance:com.webtest.demo.Test02@37374a5e]" name="test01" duration-ms="8" started-at="2020-12-03T11:07:49 CST" finished-at="2020-12-03T11:07:49 CST">
          <reporter-output>
          </reporter-output>
        </test-method> <!-- test01 -->
        <test-method status="FAIL" signature="test02()[pri:0, instance:com.webtest.demo.Test02@37374a5e]" name="test02" duration-ms="1" started-at="2020-12-03T11:07:49 CST" finished-at="2020-12-03T11:07:49 CST">
          <exception class="java.lang.AssertionError">
            <message>
              <![CDATA[expected [2] but found [1]]]>
            </message>
            <full-stacktrace>
              <![CDATA[java.lang.AssertionError: expected [2] but found [1]
at org.testng.Assert.fail(Assert.java:97)
at org.testng.Assert.assertEqualsImpl(Assert.java:136)
at org.testng.Assert.assertEquals(Assert.java:118)
at org.testng.Assert.assertEquals(Assert.java:839)
at org.testng.Assert.assertEquals(Assert.java:849)
at com.webtest.demo.Test02.test02(Test02.java:29)
at sun.reflect.NativeMethodAccessorImpl.invoke0(Native Method)
at sun.reflect.NativeMethodAccessorImpl.invoke(Unknown Source)
at sun.reflect.DelegatingMethodAccessorImpl.invoke(Unknown Source)
at java.lang.reflect.Method.invoke(Unknown Source)
at org.testng.internal.MethodInvocationHelper.invokeMethod(MethodInvocationHelper.java:134)
at org.testng.internal.TestInvoker.invokeMethod(TestInvoker.java:597)
at org.testng.internal.TestInvoker.invokeTestMethod(TestInvoker.java:173)
at org.testng.internal.MethodRunner.runInSequence(MethodRunner.java:46)
at org.testng.internal.TestInvoker$MethodInvocationAgent.invoke(TestInvoker.java:816)
at org.testng.internal.TestInvoker.invokeTestMethods(TestInvoker.java:146)
at org.testng.internal.TestMethodWorker.invokeTestMethods(TestMethodWorker.java:146)
at org.testng.internal.TestMethodWorker.run(TestMethodWorker.java:128)
at java.util.ArrayList.forEach(Unknown Source)
at org.testng.TestRunner.privateRun(TestRunner.java:766)
at org.testng.TestRunner.run(TestRunner.java:587)
at org.testng.SuiteRunner.runTest(SuiteRunner.java:384)
at org.testng.SuiteRunner.runSequentially(SuiteRunner.java:378)
at org.testng.SuiteRunner.privateRun(SuiteRunner.java:337)
at org.testng.SuiteRunner.run(SuiteRunner.java:286)
at org.testng.SuiteRunnerWorker.runSuite(SuiteRunnerWorker.java:53)
at org.testng.SuiteRunnerWorker.run(SuiteRunnerWorker.java:96)
at org.testng.TestNG.runSuitesSequentially(TestNG.java:1187)
at org.testng.TestNG.runSuitesLocally(TestNG.java:1109)
at org.testng.TestNG.runSuites(TestNG.java:1039)
at org.testng.TestNG.run(TestNG.java:1007)
at org.testng.remote.AbstractRemoteTestNG.run(AbstractRemoteTestNG.java:115)
at org.testng.remote.RemoteTestNG.initAndRun(RemoteTestNG.java:251)
at org.testng.remote.RemoteTestNG.main(RemoteTestNG.java:77)
]]>
            </full-stacktrace>
          </exception> <!-- java.lang.AssertionError -->
          <reporter-output>
          </reporter-output>
        </test-method> <!-- test02 -->
        <test-method status="PASS" signature="test03()[pri:0, instance:com.webtest.demo.Test02@37374a5e]" name="test03" duration-ms="1" started-at="2020-12-03T11:07:49 CST" finished-at="2020-12-03T11:07:49 CST">
          <reporter-output>
          </reporter-output>
        </test-method> <!-- test03 -->
      </class> <!-- com.webtest.demo.Test02 -->
    </test> <!-- t2 -->
  </suite> <!-- s1 -->
</testng-results>
